В C++ блок `try-catch` используется для обработки исключений. Это позволяет программе перехватывать и обрабатывать ошибки или исключительные ситуации, которые могут возникнуть во время выполнения программы. 

Вот общий синтаксис `try-catch`:
```cpp
try {
    // Блок кода, в котором может возникнуть исключение
    // ...
    // Код, который может привести к исключительной ситуации
    // ...
} catch (ТипИсключения параметр) {
    // Блок кода, который выполняется, если возникает исключение
    // Обработка исключения
    // ...
} catch (ДругойТипИсключения параметр) {
    // Обработка другого типа исключения, если необходимо
    // ...
} catch (...) {
    // Обработка всех остальных типов исключений
    // Этот блок будет выполнен, если произойдет исключение, не совпадающее с предыдущими catch блоками
}
```

- В блоке `try` размещается код, который может вызвать исключение.
- Если в блоке `try` возникает исключение, управление передается соответствующему блоку `catch`.
- `catch` блоки предоставляются для обработки различных типов исключений. Вы можете иметь несколько `catch` блоков для обработки различных типов исключений.
- Параметр, передаваемый в `catch`, используется для получения информации об исключении, которое было сгенерировано. Вы можете использовать этот параметр для отладки или выполнения дополнительных действий в зависимости от типа исключения.

## Пример использования `try-catch`:

### Обработка исключения типа `std::exception`

```cpp
#include <iostream>
using namespace std;

int main() {
    try {
        int x = 10;
        int y = 0;
        if (y == 0) {
            throw "Деление на ноль!";
        }
        int result = x / y;
        cout << "Результат деления: " << result;
    } catch (const char* message) {
        cout << "Ошибка: " << message;
    }
    return 0;
}
```

### Множественные блоки `catch` для разных типов исключений

```cpp
#include <iostream>
#include <stdexcept>
using namespace std;

int main() {
    try {
        int x = 10;
        int y = 0;
        if (y == 0) {
            throw runtime_error("Деление на ноль!");
        }
        int result = x / y;
        cout << "Результат деления: " << result;
    } catch (const runtime_error& e) {
        cout << "Ошибка: " << e.what();
    } catch (const exception& e) {
        cout << "Общая ошибка: " << e.what();
    }
    return 0;
}
```

В этом примере блок `catch` для `runtime_error` исключений расположен первым, что позволяет обрабатывать специфичные ошибки в первую очередь. Если тип исключения не соответствует первому блоку `catch`, то выполнение перейдет к следующему блоку `catch`.

### Обработка неизвестных исключений с помощью `...` catch

```cpp
#include <iostream>
using namespace std;

int main() {
    try {
        int x = 10;
        int y = 0;
        if (y == 0) {
            throw "Деление на ноль!";
        }
        int result = x / y;
        cout << "Результат деления: " << result;
    } catch (...) {
        cout << "Произошла неизвестная ошибка";
    }
    return 0;
}
```

В этом примере блок `catch` с `...` будет обрабатывать все типы исключений, которые не были обработаны предыдущими блоками `catch`. Это может быть полезно для обработки неожиданных ошибок или для логирования их.